Workbook

Sheet Worklog_Tasks&Times
A1: Date | B1: Status | C1: Task | D1: Description/Planning | E1: Task Type | F1: Most suited ILO | G1: Est Hours | H1: Actual Hours | I1: Diff | J1: Evidence link | K1: Task reflection / notes
A2: Week 1
A3: week plan: | B3: - Weekplan item 1 - Weekplan item 2 - Weekplan item 3 - etc
A4: Known Risks | B4: [Enter known possible issues that are a risk for you to finish the high level week planning]
A5: 45698 | B5: Done | C5: Creative brief | D5: Reading Creative brief contents | E5: Study | F5: ILO 1.3 | G5: 2 | H5: 2 | I5: =H5-G5 -> 0 | J5: Starting Block C | K5: Reading and trying to undrestand what we should do this Block
A6: 45698 | B6: Done | C6: Data lab content | D6: Reading data lab content | E6: Study | F6: ILO 1.3 | G6: 3 | H6: 3 | I6: =H6-G6 -> 0 | J6: Monday datalab
A7: 45699 | B7: Done | C7: Business Understanding | D7: I have completed data lab task | E7: Research | F7: ILO 1.3 | G7: 2 | H7: 2 | I7: =H7-G7 -> 0 | J7: Business Understanding | K7: Doing task 1,1 and 1,2 of Business Undrestanding template
A8: 45699 | B8: Done | C8: Presentation | D8: I attended to the kick off presentation | E8: Lecture | F8: - | G8: 3 | H8: 3 | I8: =H8-G8 -> 0
A9: 45699 | B9: Done | C9: Business Understanding | D9: Completeing task 1,3 and 1,4 | E9: Research | F9: ILO 1.3 | G9: 3 | H9: 3 | I9: =H9-G9 -> 0 | J9: Business Understanding | K9: I hada a problem to create a daps diagram that is why it took more time
A10: 45700 | B10: Done | C10: Data lab content | D10: Reading data lab content | E10: Study | F10: ILO 1.3 | G10: 3 | H10: 3 | I10: =H10-G10 -> 0 | J10: Wednesday data lab
A11: 45700 | B11: Done | C11: Assignment | D11: I have completed Wednesday assignment | E11: Testing | F11: ILO 1.3 | G11: 1 | H11: 1 | I11: =H11-G11 -> 0 | J11: Wednesday Quizz
A12: 45701 | B12: Done | C12: Data lab content | D12: Reading Thuursday data lab content | E12: Study | F12: ILO 1.3 | G12: 3 | H12: 3 | I12: =H12-G12 -> 0 | J12: Thusrday Data lab | K12: Definition of Fairness and bias
A13: 45701 | B13: Done | C13: Thursday quizz | D13: completing Thursday quizz | E13: Testing | F13: ILO 1.3 | G13: 2 | H13: 2 | I13: =H13-G13 -> 0 | J13: Thursday quizz
A14: 45702 | B14: Done | C14: Friday data lab content | D14: collecting data set | E14: Research | F14: ILO 1.3 | G14: 3 | H14: 3 | I14: =H14-G14 -> 0 | J14: Collecting data set | K14: Because I was sick on Friday I couldn't study more.
A15: 45703 | B15: Done | C15: Collecting data set | D15: Collecting data set | E15: Research | F15: ILO 1.3 | G15: 4 | H15: 4 | I15: =H15-G15 -> 0 | J15: Generative AI pictures | K15: Collecting data set via generative AI and web scrapping.
A16: 45704 | B16: Done | C16: Collecting data set | D16: Collecting data set | E16: Research | F16: ILO 1.3 | G16: 4 | H16: 4 | I16: =H16-G16 -> 0 | J16: Finall Dataset
E17: Total Hours | G17: =SUM(G5:G16) -> 33 | H17: =SUM(H5:H16) -> 33 | I17: =H17-G17 -> 0
A18: Week 2
A19: week plan: | B19: - Weekplan item 1 - Weekplan item 2 - Weekplan item 3 - etc
A20: Known Risks | B20: [Enter known possible issues that are a risk for you to finish the high level week planning] - if any
A21: 45705 | B21: Done | C21: Data lab content | D21: Reading data lab content | E21: Study | F21: ILO 1.3 | G21: 4 | H21: 5 | I21: =H21-G21 -> 1 | J21: Data lab Monday | K21: The last part was so confusing for me that is why it take more time for me
A22: 45705 | B22: Done | C22: Monday Quizz | D22: completed Monday quizz | E22: Testing | F22: ILO 1.3 | G22: 1 | H22: 1 | I22: =H22-G22 -> 0 | J22: Monday Quizz
A23: 45706 | B23: Done | C23: Lecture | D23: Attending to Lecture | E23: Lecture | F23: ILO 2.3 | G23: 1.5 | H23: 1.5 | I23: =H23-G23 -> 0 | J23: Public speaking lecture
A24: 45706 | B24: Done | C24: Group fairness lecture | D24: Attending to Lecture | E24: Lecture | F24: ILO 2.3 | G24: 1 | H24: 1 | I24: =H24-G24 -> 0 | J24: Group fairness lecture
A25: 45706 | B25: Done | C25: Responsible AI | D25: Completing task 2,3 and 2,4 of Responsible AI template | E25: Testing | F25: ILO 2.3 | G25: 4 | H25: 4 | I25: =H25-G25 -> 0
A26: 45707 | B26: Done | C26: Data lab content | D26: Reading data lab content Socratic dialogue | E26: Study | F26: ILO 2.3 | G26: 3 | H26: 3 | I26: =H26-G26 -> 0 | J26: Socratic Dialogue
A27: 45707 | B27: Done | C27: Socratic preparation | E27: Study | F27: ILO 2.3 | G27: 2 | H27: 2 | I27: =H27-G27 -> 0 | K27: I'm preparing a Socratic dialogue for tomorrow and writing it on A4 pages, divided into five phases.
A28: 45707 | B28: Done | C28: Responsible AI | D28: task 2,1 of Responsible AI | E28: Research | F28: ILO 2.3 | G28: 2 | H28: 2 | I28: =H28-G28 -> 0 | J28: Task 2.1: Socratic Dialogue
A29: 45708 | B29: Done | C29: Book | D29: Deep learning with python | E29: Study | F29: ILO 6.2 | G29: 2 | H29: 2 | I29: =H29-G29 -> 0 | K29: Reading chapter 1 and 2 of Deep learning with python
A30: 45708 | B30: Done | C30: Data camp course | D30: Attending to data camp course 1 and 2 | E30: Study | F30: ILO 2.3 | G30: 2 | H30: 2 | I30: =H30-G30 -> 0 | J30: Datacamp Certificate
A31: 45708 | B31: Done | C31: Thursday quizz | D31: I have completed Thursday quizz | E31: Testing | F31: ILO 2.3 | G31: 1.5 | H31: 1.5 | I31: =H31-G31 -> 0 | J31: Thursday Quizz | K31: I was checking my answers with book context that is why it took more time than usual.
A32: 45709 | B32: Done | C32: Student notebook | D32: I have completed student notebook for mlp | E32: Programming | F32: ILO 2.3 | G32: 1 | H32: 1 | I32: =H32-G32 -> 0 | J32: Practical Assignment
A33: 45709 | B33: Done | C33: Data lab content | D33: I have completely read data lab content | E33: Study | F33: ILO 2.3 | G33: 2 | H33: 2 | J33: Practical Assignment
A34: 45710 | B34: Done | C34: Deep learning | D34: restudy book | E34: Study | F34: ILO 2.3 | G34: 2 | H34: 2 | I34: =H34-G34 -> 0 | J34: Practical Assignment | K34: Study book chapters 2 and 3 to understand the material better, and start working on the Deep Learning template.
E35: Total Hours | G35: =SUM(G19:G34) -> 29 | H35: =SUM(H19:H34) -> 30 | I35: =H35-G35 -> 1
A36: Week 3
A37: week plan: | B37: - Weekplan item 1 - Weekplan item 2 - Weekplan item 3 - etc
A38: Known Risks | B38: [Enter known possible issues that are a risk for you to finish the high level week planning]
A39: 45740 | B39: Done | C39: Datacamp | D39: watching Keras course on datacamp | E39: Study | F39: ILO 8.2 | G39: 2 | H39: 2 | I39: =H39-G39 -> 0 | J39: Datacamp Keras | K39: I finished the DataCamp course on Keras. It was very useful and explained the concepts really well, with clear and detailed explanations.
A40: 45740 | B40: Done | C40: Deep learning with python | D40: Studying deep learning with python chapter 3 and 4 | E40: Study | F40: ILO 6.2 | G40: 3 | H40: 3 | I40: =H40-G40 -> 0
...

Sheet Overview
B2: Learning Objective | C2: W1 | D2: W2 | E2: W3 | F2: W4 | G2: W5 | H2: W6 | I2: W7 | J2: W8 | K2: Total Hours for objective
B3: ='Drop-downs'!C2 -> - | K3: =SUM(C3:J3) -> 0
B4: ='Drop-downs'!C3 -> ILO 1.3 | C4: {=IFERROR(SUM(_xlfn._xlws.FILTER('Worklog_Tasks&Times'!$H$5:$H$16,'Worklog_Tasks&Times'!$F$5:$F$16=$B4)),0)} -> 30 | D4: {=IFERROR(SUM(_xlfn._xlws.FILTER('Worklog_Tasks&Times'!$H$21:$H$34,'Worklog_Tasks&Times'!$F$21:$F$34=$B4)),0)} -> 6 | E4: {=IFERROR(SUM(_xlfn._xlws.FILTER('Worklog_Tasks&Times'!$H$39:$H$48,'Worklog_Tasks&Times'!$F$39:$F$48=$B4)),0)} -> 0 | F4: {=IFERROR(SUM(_xlfn._xlws.FILTER('Worklog_Tasks&Times'!$H$53:$H$64,'Worklog_Tasks&Times'!$F$53:$F$64=$B4)),0)} -> 0 | G4: {=IFERROR(SUM(_xlfn._xlws.FILTER('Worklog_Tasks&Times'!$H$69:$H$79,'Worklog_Tasks&Times'!$F$69:$F$81=$B4)),0)} -> 0 | H4: {=IFERROR(SUM(_xlfn._xlws.FILTER('Worklog_Tasks&Times'!$H$86:$H$96,'Worklog_Tasks&Times'!$F$86:$F$96=$B4)),0)} -> 0 | I4: {=IFERROR(SUM(_xlfn._xlws.FILTER('Worklog_Tasks&Times'!$H$101:$H$110,'Worklog_Tasks&Times'!$F$101:$F$110=$B4)),0)} -> 0 | J4: {=IFERROR(SUM(_xlfn._xlws.FILTER('Worklog_Tasks&Times'!$H$115:$H$124,'Worklog_Tasks&Times'!$F$115:$F$124=$B4)),0)} -> 3 | K4: =SUM(C4:J4) -> 39
B5: ='Drop-downs'!C4 -> ILO 2.3 | C5: {=IFERROR(SUM(_xlfn._xlws.FILTER('Worklog_Tasks&Times'!$H$5:$H$16,'Worklog_Tasks&Times'!$F$5:$F$16=$B5)),0)} -> 0 | D5: {=IFERROR(SUM(_xlfn._xlws.FILTER('Worklog_Tasks&Times'!$H$21:$H$34,'Worklog_Tasks&Times'!$F$21:$F$34=$B5)),0)} -> 22 | E5: {=IFERROR(SUM(_xlfn._xlws.FILTER('Worklog_Tasks&Times'!$H$39:$H$48,'Worklog_Tasks&Times'!$F$39:$F$48=$B5)),0)} -> 0 | F5: {=IFERROR(SUM(_xlfn._xlws.FILTER('Worklog_Tasks&Times'!$H$53:$H$64,'Worklog_Tasks&Times'!$F$53:$F$64=$B5)),0)} -> 0 | G5: {=IFERROR(SUM(_xlfn._xlws.FILTER('Worklog_Tasks&Times'!$H$69:$H$79,'Worklog_Tasks&Times'!$F$69:$F$81=$B5)),0)} -> 0 | H5: {=IFERROR(SUM(_xlfn._xlws.FILTER('Worklog_Tasks&Times'!$H$86:$H$96,'Worklog_Tasks&Times'!$F$86:$F$96=$B5)),0)} -> 4 | I5: {=IFERROR(SUM(_xlfn._xlws.FILTER('Worklog_Tasks&Times'!$H$101:$H$110,'Worklog_Tasks&Times'!$F$101:$F$110=$B5)),0)} -> 2 | J5: {=IFERROR(SUM(_xlfn._xlws.FILTER('Worklog_Tasks&Times'!$H$115:$H$124,'Worklog_Tasks&Times'!$F$115:$F$124=$B5)),0)} -> 0 | K5: =SUM(C5:J5) -> 28
B6: ='Drop-downs'!C5 -> ILO 3.2 | C6: {=IFERROR(SUM(_xlfn._xlws.FILTER('Worklog_Tasks&Times'!$H$5:$H$16,'Worklog_Tasks&Times'!$F$5:$F$16=$B6)),0)} -> 0 | D6: {=IFERROR(SUM(_xlfn._xlws.FILTER('Worklog_Tasks&Times'!$H$21:$H$34,'Worklog_Tasks&Times'!$F$21:$F$34=$B6)),0)} -> 0 | E6: {=IFERROR(SUM(_xlfn._xlws.FILTER('Worklog_Tasks&Times'!$H$39:$H$48,'Worklog_Tasks&Times'!$F$39:$F$48=$B6)),0)} -> 0 | F6: {=IFERROR(SUM(_xlfn._xlws.FILTER('Worklog_Tasks&Times'!$H$53:$H$64,'Worklog_Tasks&Times'!$F$53:$F$64=$B6)),0)} -> 0 | G6: {=IFERROR(SUM(_xlfn._xlws.FILTER('Worklog_Tasks&Times'!$H$69:$H$79,'Worklog_Tasks&Times'!$F$69:$F$81=$B6)),0)} -> 0 | H6: {=IFERROR(SUM(_xlfn._xlws.FILTER('Worklog_Tasks&Times'!$H$86:$H$96,'Worklog_Tasks&Times'!$F$86:$F$96=$B6)),0)} -> 4 | I6: {=IFERROR(SUM(_xlfn._xlws.FILTER('Worklog_Tasks&Times'!$H$101:$H$110,'Worklog_Tasks&Times'!$F$101:$F$110=$B6)),0)} -> 22 | J6: {=IFERROR(SUM(_xlfn._xlws.FILTER('Worklog_Tasks&Times'!$H$115:$H$124,'Worklog_Tasks&Times'!$F$115:$F$124=$B6)),0)} -> 0 | K6: =SUM(C6:J6) -> 26
B7: ='Drop-downs'!C6 -> ILO 4.1 | C7: {=IFERROR(SUM(_xlfn._xlws.FILTER('Worklog_Tasks&Times'!$H$5:$H$16,'Worklog_Tasks&Times'!$F$5:$F$16=$B7)),0)} -> 0 | D7: {=IFERROR(SUM(_xlfn._xlws.FILTER('Worklog_Tasks&Times'!$H$21:$H$34,'Worklog_Tasks&Times'!$F$21:$F$34=$B7)),0)} -> 0 | E7: {=IFERROR(SUM(_xlfn._xlws.FILTER('Worklog_Tasks&Times'!$H$39:$H$48,'Worklog_Tasks&Times'!$F$39:$F$48=$B7)),0)} -> 0 | F7: {=IFERROR(SUM(_xlfn._xlws.FILTER('Worklog_Tasks&Times'!$H$53:$H$64,'Worklog_Tasks&Times'!$F$53:$F$64=$B7)),0)} -> 0 | G7: {=IFERROR(SUM(_xlfn._xlws.FILTER('Worklog_Tasks&Times'!$H$69:$H$79,'Worklog_Tasks&Times'!$F$69:$F$81=$B7)),0)} -> 0 | H7: {=IFERROR(SUM(_xlfn._xlws.FILTER('Worklog_Tasks&Times'!$H$86:$H$96,'Worklog_Tasks&Times'!$F$86:$F$96=$B7)),0)} -> 0 | I7: {=IFERROR(SUM(_xlfn._xlws.FILTER('Worklog_Tasks&Times'!$H$101:$H$110,'Worklog_Tasks&Times'!$F$101:$F$110=$B7)),0)} -> 0 | J7: {=IFERROR(SUM(_xlfn._xlws.FILTER('Worklog_Tasks&Times'!$H$115:$H$124,'Worklog_Tasks&Times'!$F$115:$F$124=$B7)),0)} -> 0 | K7: =SUM(C7:J7) -> 0
B8: ='Drop-downs'!C7 -> ILO 6.2 | C8: {=IFERROR(SUM(_xlfn._xlws.FILTER('Worklog_Tasks&Times'!$H$5:$H$16,'Worklog_Tasks&Times'!$F$5:$F$16=$B8)),0)} -> 0 | D8: {=IFERROR(SUM(_xlfn._xlws.FILTER('Worklog_Tasks&Times'!$H$21:$H$34,'Worklog_Tasks&Times'!$F$21:$F$34=$B8)),0)} -> 2 | E8: {=IFERROR(SUM(_xlfn._xlws.FILTER('Worklog_Tasks&Times'!$H$39:$H$48,'Worklog_Tasks&Times'!$F$39:$F$48=$B8)),0)} -> 4 | F8: {=IFERROR(SUM(_xlfn._xlws.FILTER('Worklog_Tasks&Times'!$H$53:$H$64,'Worklog_Tasks&Times'!$F$53:$F$64=$B8)),0)} -> 4 | G8: {=IFERROR(SUM(_xlfn._xlws.FILTER('Worklog_Tasks&Times'!$H$69:$H$79,'Worklog_Tasks&Times'!$F$69:$F$81=$B8)),0)} -> 0 | H8: {=IFERROR(SUM(_xlfn._xlws.FILTER('Worklog_Tasks&Times'!$H$86:$H$96,'Worklog_Tasks&Times'!$F$86:$F$96=$B8)),0)} -> 6 | I8: {=IFERROR(SUM(_xlfn._xlws.FILTER('Worklog_Tasks&Times'!$H$101:$H$110,'Worklog_Tasks&Times'!$F$101:$F$110=$B8)),0)} -> 0 | J8: {=IFERROR(SUM(_xlfn._xlws.FILTER('Worklog_Tasks&Times'!$H$115:$H$124,'Worklog_Tasks&Times'!$F$115:$F$124=$B8)),0)} -> 4 | K8: =SUM(C8:J8) -> 20
B9: ='Drop-downs'!C8 -> ILO 8.2 | C9: {=IFERROR(SUM(_xlfn._xlws.FILTER('Worklog_Tasks&Times'!$H$5:$H$16,'Worklog_Tasks&Times'!$F$5:$F$16=$B9)),0)} -> 0 | D9: {=IFERROR(SUM(_xlfn._xlws.FILTER('Worklog_Tasks&Times'!$H$21:$H$34,'Worklog_Tasks&Times'!$F$21:$F$34=$B9)),0)} -> 0 | E9: {=IFERROR(SUM(_xlfn._xlws.FILTER('Worklog_Tasks&Times'!$H$39:$H$48,'Worklog_Tasks&Times'!$F$39:$F$48=$B9)),0)} -> 16 | F9: {=IFERROR(SUM(_xlfn._xlws.FILTER('Worklog_Tasks&Times'!$H$53:$H$64,'Worklog_Tasks&Times'!$F$53:$F$64=$B9)),0)} -> 25 | G9: {=IFERROR(SUM(_xlfn._xlws.FILTER('Worklog_Tasks&Times'!$H$69:$H$79,'Worklog_Tasks&Times'!$F$69:$F$81=$B9)),0)} -> 0 | H9: {=IFERROR(SUM(_xlfn._xlws.FILTER('Worklog_Tasks&Times'!$H$86:$H$96,'Worklog_Tasks&Times'!$F$86:$F$96=$B9)),0)} -> 3 | I9: {=IFERROR(SUM(_xlfn._xlws.FILTER('Worklog_Tasks&Times'!$H$101:$H$110,'Worklog_Tasks&Times'!$F$101:$F$110=$B9)),0)} -> 4 | J9: {=IFERROR(SUM(_xlfn._xlws.FILTER('Worklog_Tasks&Times'!$H$115:$H$124,'Worklog_Tasks&Times'!$F$115:$F$124=$B9)),0)} -> 4 | K9: =SUM(C9:J9) -> 52
B10: ='Drop-downs'!C9 -> ILO 9.1 | C10: {=IFERROR(SUM(_xlfn._xlws.FILTER('Worklog_Tasks&Times'!$H$5:$H$16,'Worklog_Tasks&Times'!$F$5:$F$16=$B10)),0)} -> 0 | D10: {=IFERROR(SUM(_xlfn._xlws.FILTER('Worklog_Tasks&Times'!$H$21:$H$34,'Worklog_Tasks&Times'!$F$21:$F$34=$B10)),0)} -> 0 | E10: {=IFERROR(SUM(_xlfn._xlws.FILTER('Worklog_Tasks&Times'!$H$39:$H$48,'Worklog_Tasks&Times'!$F$39:$F$48=$B10)),0)} -> 7 | F10: {=IFERROR(SUM(_xlfn._xlws.FILTER('Worklog_Tasks&Times'!$H$53:$H$64,'Worklog_Tasks&Times'!$F$53:$F$64=$B10)),0)} -> 6 | G10: {=IFERROR(SUM(_xlfn._xlws.FILTER('Worklog_Tasks&Times'!$H$69:$H$79,'Worklog_Tasks&Times'!$F$69:$F$81=$B10)),0)} -> 0 | H10: {=IFERROR(SUM(_xlfn._xlws.FILTER('Worklog_Tasks&Times'!$H$86:$H$96,'Worklog_Tasks&Times'!$F$86:$F$96=$B10)),0)} -> 19 | I10: {=IFERROR(SUM(_xlfn._xlws.FILTER('Worklog_Tasks&Times'!$H$101:$H$110,'Worklog_Tasks&Times'!$F$101:$F$110=$B10)),0)} -> 0 | J10: {=IFERROR(SUM(_xlfn._xlws.FILTER('Worklog_Tasks&Times'!$H$115:$H$124,'Worklog_Tasks&Times'!$F$115:$F$124=$B10)),0)} -> 16 | K10: =SUM(C10:J10) -> 48
B11: TOTAL HOURS PER WEEK | C11: =SUM(C3:C10) -> 30 | D11: =SUM(D3:D10) -> 30 | E11: =SUM(E3:E10) -> 27 | F11: =SUM(F3:F10) -> 35 | G11: =SUM(G3:G10) -> 0 | H11: =SUM(H3:H10) -> 36 | I11: =SUM(I3:I10) -> 28 | J11: =SUM(J3:J10) -> 27
B13: Use this to plan a high level allocation for all 320 hours you are expected to devote to the course during this block. How do you want to allocate your hours for each week? Why 320 hours? The European Higher Education Framework states that an academic credit is expected to require 25-28 hours to earn. You earn 15 credits per block, so you should be expected to devote 375 hours to accomplish that. CMGT students do fewer hours because the program is more intense.
B17: If you add more rows to the Worklog Tasks and Time sheet, make sure to update the row count accordingly. For example, if you add an additional row for Week 1, you'll need to adjust all formula in Column C from H14 to H15 and F14 to F15

Sheet Drop-downs
A1: Task Status | B1: Task Type | C1: ILO selection
A2: - | B2: - | C2: -
A3: Planned | B3: Design | C3: ILO 1.3
A4: Unplanned | B4: Meeting | C4: ILO 2.3
A5: Blocked | B5: Programming | C5: ILO 3.2
A6: In-Progress | B6: Research | C6: ILO 4.1
A7: Done | B7: Testing | C7: ILO 6.2
A8: Delayed | B8: Workshop | C8: ILO 8.2
A9: Cancelled | B9: Planning | C9: ILO 9.1
B10: Evidencing
B11: Debugging
B12: Lecture
B13: Study
B14: Unplanned
B15: Distraction
B16: Break
